Workbook

Sheet Medicine_Sales_MessyData_2025
A1: Sale_ID | B1: Sale_Date | C1: Region | D1: State | E1: City | F1: Gender | G1: Age_Group | H1: Season | I1: Disease | J1: Medicine_Name | K1: Quantity_Sold | L1: Unit_Price | M1: Discount_% | N1: Total_Amount | O1: Sales_Channel | P1: Payment_Mode | Q1: Doctor_Prescribed | R1: Return_Flag | S1: Customer_Rating | T1: Remarks
A2: 1 | B2: 45985 | C2: North | D2: CA | E2: City_48 | F2: Other | G2: 19-35 | H2: Summer | I2: Diabetes | J2: MedA | K2: 44 | L2: 75.36 | O2: Online | P2: cash | Q2: Yes | R2: Y | S2: 1 | T2: Repeat customer
A3: 2 | B3: 45777 | C3: Central | D3: IL | E3: City_2 | F3: F | G3: 19-35 | H3: winter | I3: Cold | J3: MedB | K3: 29 | L3: 60.98 | M3: 0 | O3: Retail | P3: cash | Q3: yes | R3: N | S3: 2 | T3: Repeat customer
A4: 3 | B4: 45830 | C4: North | D4: CA | E4: City_25 | F4: Male | G4: 36-60 | H4: Monsoon | I4: Asthma | J4: MedC | K4: 3 | L4: 74.32 | O4: Online | P4: cash | Q4: Yes | S4: 3 | T4: First visit
A5: 4 | B5: 45953 | C5: South | D5: ca | E5: City_5 | F5: Male | H5: Summer | I5: Hypertension | J5: MedA | K5: 15 | L5: 87.32 | M5: 15 | O5: Hospital | P5: cash | Q5: yes | R5: Y | S5: 3 | T5: First visit
A6: 5 | B6: 45765 | C6: north | D6: NY | E6: City_45 | H6: Winter | I6: Asthma | J6: MedB | K6: 35 | L6: 74.27 | M6: 5 | O6: online | P6: cash | Q6: yes | T6: Repeat customer
A7: 6 | B7: 46008 | C7: East | D7: Tx | E7: City_50 | F7: Male | G7: 19-35 | H7: Winter | I7: Hypertension | J7: MedD | K7: 18 | L7: 11.29 | O7: Hospital | P7: Card | Q7: no | R7: N
A8: 7 | B8: 45731 | C8: East | D8: TX | E8: City_16 | G8: 19 -35 | H8: winter | I8: Hypertension | J8: MedD | K8: 38 | L8: 42.94 | M8: 5 | O8: Retail | P8: cash | Q8: Yes | R8: Y | S8: 1 | T8: Repeat customer
A9: 8 | B9: 45979 | C9: South | D9: Tx | E9: City_44 | F9: M | G9: 19 -35 | H9: Winter | I9: Cold | J9: MedD | K9: 39 | L9: 99.63 | O9: Hospital | P9: Cash | Q9: Yes | S9: 5 | T9: First visit
A10: 9 | B10: 45986 | C10: East | D10: CA | E10: City_19 | F10: M | G10: 19-35 | H10: Spring | I10: Flu | J10: MedC | K10: 33 | L10: 77.39 | O10: Online | P10: UPI | Q10: No | R10: Y | S10: 3 | T10: Repeat customer
A11: 10 | B11: 45934 | C11: SOUTH | D11: IL | E11: City_1 | F11: F | G11: 36-60 | H11: Spring | I11: Flu | J11: MedA | K11: 24 | L11: 88.48 | M11: 10 | O11: Retail | P11: Cash | Q11: No | S11: 1
A12: 11 | B12: 45906 | C12: SOUTH | D12: CA | E12: City_49 | F12: F | G12: 19-35 | H12: Summer | I12: Cold | J12: MedB | K12: 17 | L12: 55.13 | O12: online | P12: Card | Q12: No | S12: 3
A13: 12 | B13: 46001 | C13: north | D13: NY | E13: City_29 | F13: F | G13: 60+ | H13: Winter | I13: Diabetes | J13: MedB | K13: 5 | L13: 37.12 | O13: Retail | P13: Card | Q13: Yes | R13: Y
A14: 13 | B14: 45775 | C14: North | D14: CA | E14: City_22 | F14: Male | G14: 19 -35 | H14: Summer | I14: Hypertension | J14: MedD | K14: 14 | L14: 56.23 | O14: online | P14: Card | Q14: no | R14: N | S14: 2
A15: 14 | B15: 45707 | C15: north | D15: FL | E15: City_23 | F15: M | G15: 60+ | H15: Spring | I15: Flu | J15: MedA | K15: 4 | L15: 43.25 | M15: 10 | O15: Online | P15: Card | Q15: No | R15: Y | S15: 5
A16: 15 | B16: 45729 | C16: West | D16: TX | E16: City_18 | F16: M | G16: 19-35 | H16: Winter | I16: Cold | J16: MedA | K16: 4 | L16: 66.95 | O16: Online | P16: Cash | Q16: No | R16: Y | S16: 4
A17: 16 | B17: 45904 | C17: South | D17: Tx | E17: City_26 | F17: Male | G17: 19-35 | H17: Spring | I17: Flu | J17: MedD | K17: 17 | L17: 93.02 | M17: 15 | O17: Hospital | P17: cash | Q17: no | R17: Y | S17: 2 | T17: First visit
A18: 17 | B18: 45769 | C18: North | D18: IL | E18: City_48 | F18: F | G18: 0-18 | H18: Monsoon | I18: Flu | J18: MedA | K18: 38 | L18: 50.29 | O18: Retail | P18: Cash | Q18: Yes | R18: Y | S18: 1
A19: 18 | B19: 46003 | C19: SOUTH | D19: TX | E19: City_26 | F19: Male | G19: 19 -35 | H19: Summer | I19: Asthma | J19: MedA | K19: 40 | L19: 12.79 | O19: Hospital | P19: UPI | Q19: No | T19: First visit
A20: 19 | B20: 45780 | C20: East | D20: FL | E20: City_9 | H20: Monsoon | I20: Cold | J20: MedC | K20: 49 | L20: 93.89 | M20: 0 | O20: online | P20: Cash | Q20: Yes | S20: 2 | T20: First visit
A21: 20 | B21: 45725 | C21: East | D21: CA | E21: City_16 | F21: Other | G21: 36-60 | H21: Summer | I21: Cold | J21: MedC | K21: 40 | L21: 98.47 | O21: Online | P21: UPI | Q21: Yes | R21: Y | S21: 3
A22: 21 | B22: 45712 | C22: north | D22: IL | E22: City_10 | F22: Other | G22: 36-60 | H22: winter | I22: Diabetes | J22: MedC | K22: 14 | L22: 70.31 | M22: 10 | O22: online | P22: UPI | Q22: Yes | R22: Y
A23: 22 | B23: 45799 | C23: North | D23: CA | E23: City_22 | F23: Female | H23: Monsoon | I23: Diabetes | J23: MedD | K23: 36 | L23: 72.04 | O23: Online | P23: Cash | Q23: Yes | S23: 2
A24: 23 | B24: 45847 | C24: Central | D24: IL | E24: City_10 | F24: M | G24: 19-35 | H24: Winter | I24: Hypertension | J24: MedC | K24: 3 | L24: 90.4 | M24: 5 | O24: Retail | P24: Cash | Q24: yes | S24: 4 | T24: Repeat customer
A25: 24 | B25: 45779 | C25: SOUTH | D25: TX | E25: City_12 | F25: M | G25: 0-18 | H25: Summer | I25: Hypertension | J25: MedD | K25: 43 | L25: 87.09 | M25: 5 | O25: Hospital | P25: Card | Q25: Yes | R25: N | S25: 1
A26: 25 | B26: 45771 | C26: South | D26: Tx | E26: City_30 | F26: Other | G26: 36-60 | H26: Summer | I26: Diabetes | J26: MedA | K26: 43 | L26: 23.35 | M26: 10 | O26: Hospital | P26: Cash | Q26: yes | R26: N
A27: 26 | B27: 46005 | C27: SOUTH | D27: IL | E27: City_22 | F27: Male | G27: 0-18 | H27: Monsoon | I27: Diabetes | J27: MedC | K27: 3 | L27: 15.3 | M27: 15 | O27: Hospital | P27: UPI | Q27: no | S27: 5
A28: 27 | B28: 45855 | C28: Central | D28: TX | E28: City_17 | F28: Male | H28: Spring | I28: Flu | J28: MedB | K28: 24 | L28: 45.97 | M28: 10 | O28: Hospital | P28: Cash | Q28: yes | S28: 3
A29: 28 | B29: 45825 | C29: West | D29: ca | E29: City_19 | F29: F | G29: 19-35 | H29: Summer | I29: Cold | J29: MedD | K29: 44 | L29: 76.07 | M29: 5 | O29: Hospital | P29: cash | Q29: Yes | R29: N | S29: 3 | T29: Repeat customer
A30: 29 | B30: 45878 | C30: SOUTH | D30: IL | E30: City_39 | G30: 36-60 | H30: Spring | I30: Cold | J30: MedD | K30: 44 | L30: 25.3 | M30: 15 | O30: Retail | P30: Cash | Q30: yes | T30: First visit
A31: 30 | B31: 45705 | C31: SOUTH | D31: Tx | E31: City_16 | G31: 36-60 | H31: Summer | I31: Diabetes | J31: MedB | K31: 2 | L31: 9.39 | M31: 15 | O31: Online | P31: cash | Q31: no | S31: 5 | T31: Repeat customer
A32: 31 | B32: 46014 | C32: West | D32: FL | E32: City_26 | F32: Female | G32: 19-35 | H32: Winter | I32: Flu | J32: MedD | K32: 15 | L32: 21.71 | O32: online | P32: Cash | Q32: No | R32: Y | S32: 4 | T32: Repeat customer
A33: 32 | B33: 45895 | C33: north | D33: IL | E33: City_36 | F33: F | G33: 36-60 | H33: Spring | I33: Asthma | J33: MedD | K33: 36 | L33: 47.36 | M33: 5 | O33: online | P33: cash | Q33: yes | R33: Y | T33: First visit
A34: 33 | B34: 45924 | C34: West | D34: ca | E34: City_16 | F34: Other | G34: 60+ | H34: Winter | I34: Hypertension | J34: MedB | K34: 18 | L34: 36.91 | O34: Online | P34: Card | Q34: No | R34: Y | S34: 4 | T34: Repeat customer
A35: 34 | B35: 46019 | C35: South | D35: CA | E35: City_27 | F35: M | G35: 36-60 | H35: winter | I35: Cold | J35: MedD | K35: 4 | L35: 24.65 | M35: 15 | O35: online | P35: Cash | Q35: no | R35: N | S35: 1 | T35: First visit
A36: 35 | B36: 45810 | C36: SOUTH | D36: FL | E36: City_27 | F36: F | H36: winter | I36: Asthma | J36: MedB | K36: 32 | L36: 25.85 | M36: 15 | O36: online | P36: Cash | Q36: no | R36: N
A37: 36 | B37: 45742 | C37: SOUTH | D37: FL | E37: City_9 | F37: F | G37: 19 -35 | H37: Winter | I37: Cold | J37: MedA | K37: 6 | L37: 66.06 | M37: 5 | O37: online | P37: Card | Q37: Yes | R37: N | S37: 4 | T37: First visit
A38: 37 | B38: 45766 | C38: West | D38: NY | E38: City_22 | F38: M | G38: 36-60 | H38: Spring | I38: Hypertension | J38: MedA | K38: 31 | L38: 6.84 | O38: Online | P38: UPI | Q38: No | S38: 1
A39: 38 | B39: 45673 | C39: South | D39: TX | E39: City_2 | F39: F | G39: 19-35 | H39: Summer | I39: Diabetes | J39: MedD | K39: 43 | L39: 15.87 | M39: 5 | O39: online | P39: UPI | Q39: yes | R39: Y | S39: 5
A40: 39 | B40: 45741 | C40: East | D40: CA | E40: City_38 | F40: Male | G40: 36-60 | H40: winter | I40: Cold | J40: MedD | K40: 46 | L40: 23.84 | O40: Retail | P40: Cash | Q40: yes | S40: 5
...

Sheet Clean_DataSet
A1: Sale_ID | B1: Sale_Date | C1: Region | D1: State | E1: City | F1: Gender | G1: Age_Group | H1: Season | I1: Disease | J1: Medicine_Name | K1: Quantity_Sold | L1: Unit_Price | M1: Discount_% | N1: Total_Amount | O1: Sales_Channel | P1: Payment_Mode | Q1: Doctor_Prescribed | R1: Return_Flag | S1: Customer_Rating | T1: Remarks
A2: 1 | B2: 45985 | C2: North | D2: Ca | E2: City_48 | F2: Other | G2: 19-35 | H2: Summer | I2: Diabetes | J2: MedA | K2: 44 | L2: 75.36 | M2: 0 | N2: =PRODUCT(K2,L2) -> 3315.84 | O2: Online | P2: Cash | Q2: Yes | R2: Y | S2: 1 | T2: Repeat Customer
A3: 2 | B3: 45777 | C3: Central | D3: Il | E3: City_2 | F3: Female | G3: 19-35 | H3: Winter | I3: Cold | J3: MedB | K3: 29 | L3: 60.98 | M3: 0 | N3: =PRODUCT(K3,L3) -> 1768.42 | O3: Retail | P3: Cash | Q3: Yes | R3: N | S3: 2 | T3: Repeat Customer
A4: 3 | B4: 45830 | C4: North | D4: Ca | E4: City_25 | F4: Male | G4: 36-60 | H4: Monsoon | I4: Asthma | J4: MedC | K4: 3 | L4: 74.32 | M4: 0 | N4: =PRODUCT(K4,L4) -> 222.96 | O4: Online | P4: Cash | Q4: Yes | R4: N | S4: 3 | T4: First Visit
A5: 4 | B5: 45953 | C5: South | D5: Ca | E5: City_5 | F5: Male | G5: 26-40 | H5: Summer | I5: Hypertension | J5: MedA | K5: 15 | L5: 87.32 | M5: 15 | N5: =PRODUCT(K5,L5) -> 1309.8 | O5: Hospital | P5: Cash | Q5: Yes | R5: Y | S5: 3 | T5: First Visit
A6: 5 | B6: 45765 | C6: North | D6: Ny | E6: City_45 | F6: Unknown | G6: 26-40 | H6: Winter | I6: Asthma | J6: MedB | K6: 35 | L6: 74.27 | M6: 5 | N6: =PRODUCT(K6,L6) -> 2599.45 | O6: Online | P6: Cash | Q6: Yes | R6: N | S6: 3 | T6: Repeat Customer
A7: 6 | B7: 46008 | C7: East | D7: Tx | E7: City_50 | F7: Male | G7: 19-35 | H7: Winter | I7: Hypertension | J7: MedD | K7: 18 | L7: 11.29 | M7: 0 | N7: =PRODUCT(K7,L7) -> 203.22 | O7: Hospital | P7: Card | Q7: No | R7: N | S7: 3 | T7: No Feedback
A8: 7 | B8: 45731 | C8: East | D8: Tx | E8: City_16 | F8: Unknown | G8: 19 -35 | H8: Winter | I8: Hypertension | J8: MedD | K8: 38 | L8: 42.94 | M8: 5 | N8: =PRODUCT(K8,L8) -> 1631.72 | O8: Retail | P8: Cash | Q8: Yes | R8: Y | S8: 1 | T8: Repeat Customer
A9: 8 | B9: 45979 | C9: South | D9: Tx | E9: City_44 | F9: Male | G9: 19 -35 | H9: Winter | I9: Cold | J9: MedD | K9: 39 | L9: 99.63 | M9: 0 | N9: =PRODUCT(K9,L9) -> 3885.57 | O9: Hospital | P9: Cash | Q9: Yes | R9: N | S9: 5 | T9: First Visit
A10: 9 | B10: 45986 | C10: East | D10: Ca | E10: City_19 | F10: Male | G10: 19-35 | H10: Spring | I10: Flu | J10: MedC | K10: 33 | L10: 77.39 | M10: 0 | N10: =PRODUCT(K10,L10) -> 2553.87 | O10: Online | P10: Upi | Q10: No | R10: Y | S10: 3 | T10: Repeat Customer
A11: 10 | B11: 45934 | C11: South | D11: Il | E11: City_1 | F11: Female | G11: 36-60 | H11: Spring | I11: Flu | J11: MedA | K11: 24 | L11: 88.48 | M11: 10 | N11: =PRODUCT(K11,L11) -> 2123.52 | O11: Retail | P11: Cash | Q11: No | R11: N | S11: 1 | T11: No Feedback
A12: 11 | B12: 45906 | C12: South | D12: Ca | E12: City_49 | F12: Female | G12: 19-35 | H12: Summer | I12: Cold | J12: MedB | K12: 17 | L12: 55.13 | M12: 0 | N12: =PRODUCT(K12,L12) -> 937.21 | O12: Online | P12: Card | Q12: No | R12: N | S12: 3 | T12: No Feedback
A13: 12 | B13: 46001 | C13: North | D13: Ny | E13: City_29 | F13: Female | G13: 60+ | H13: Winter | I13: Diabetes | J13: MedB | K13: 5 | L13: 37.12 | M13: 0 | N13: =PRODUCT(K13,L13) -> 185.6 | O13: Retail | P13: Card | Q13: Yes | R13: Y | S13: 5 | T13: No Feedback
... A501: 500 | B501: 45768 | C501: South | D501: Tx | E501: City_48 | F501: Male | G501: 0-18 | H501: Winter | I501: Asthma | J501: MedC | K501: 5 | L501: 87.69 | M501: 15 | N501: =PRODUCT(K501,L501) -> 438.45 | O501: Online | P501: Upi | Q501: No | R501: N | S501: 4 | T501: No Feedback

Sheet Operation_Sheet
C2: How discounts affect total sales and revenue ?
C3: Avg_Discount | D3: =AVERAGE(Clean_DataSet!M2:M501) -> 5.79
C5: Which region and season generate the highest medicine sales?
C6: Region | D6: Season | E6: Sales
C7: North | D7: Winter | E7: =SUMIFS(Clean_DataSet!N2:N501,Clean_DataSet!C2:C501,C7,Clean_DataSet!H2:H501,D7) -> 86667.05
C9: Which age group and gender buy medicines?
C10: Gender | D10: Age_Group | E10: Result
C11: Unknown | D11: 36-60 | E11: =COUNTIFS(Clean_DataSet!F2:F501,C11,Clean_DataSet!G2:G501,D11) -> 23
C13: Selling medicines by disease and season
C14: Season | D14: Disease | E14: Result
C15: Summer | D15: Diabetes | E15: =SUMIFS(Clean_DataSet!K2:K501,Clean_DataSet!H2:H501,C15,Clean_DataSet!I2:I501,D15) -> 717
C17: Net revenue after discount ?
C18: Result
C19: {=SUMPRODUCT(Clean_DataSet!K2:K501*Clean_DataSet!L2:L501*(1-Clean_DataSet!M2:$M$501))} -> -3506892.5
C21: Which medicines generate the highest sales?
C22: Medicine_Name | D22: Result
C23: MedD | D23: {=SUMPRODUCT((Clean_DataSet!J2:J501=C23)*(Clean_DataSet!K2:K501*Clean_DataSet!L2:L501))} -> 209191.15

Sheet Pivot_Table_Sheet
A3: Season | B3: Sum of Total_Amount | D3: Region | E3: Sum of Quantity_Sold | G3: Age_Group | H3: Count of Disease | J3: Medicine_Name | K3: Sum of Quantity_Sold
A4: Monsoon | B4: 114307.76 | D4: Central | E4: 1757 | G4: 0-18 | H4: 85 | J4: MedA | K4: 3293
A5: Spring | B5: 140369.28 | D5: East | E5: 2124 | G5: 19 -35 | H5: 75 | J5: MedB | K5: 3269
A6: Summer | B6: 149362.33 | D6: North | E6: 3779 | G6: 19-35 | H6: 83 | J6: MedC | K6: 2847
A7: Winter | B7: 292031.77 | D7: South | E7: 3893 | G7: 26-40 | H7: 88 | J7: MedD | K7: 3975
D8: West | E8: 1831 | G8: 36-60 | H8: 102
G9: 60+ | H9: 67
A12: Disease | B12: Sum of Total_Amount | D12: Age_Group | E12: Sum of Total_Amount | G12: Discount_% | H12: Sum of Total_Amount | J12: Return_Flag | K12: Sum of Sale_ID | L12: Count of State
A13: Asthma | B13: 106770.91 | D13: 0-18 | E13: 123415.11 | G13: 0 | H13: 270422 | J13: N | K13: 85785 | L13: 346
A14: Cold | B14: 167091.61 | D14: 19 -35 | E14: 97467.45 | G14: 5 | H14: 157577.83 | J14: Y | K14: 39465 | L14: 154
A15: Diabetes | B15: 162238.89 | D15: 19-35 | E15: 112620.59 | G15: 10 | H15: 121199.03
A16: Flu | B16: 117715.44 | D16: 26-40 | E16: 123915.06 | G16: 15 | H16: 146872.28
A17: Hypertension | B17: 142254.29 | D17: 36-60 | E17: 152353.38
D18: 60+ | E18: 86299.55

Sheet Visualization_Sheet
